Workbook

Sheet Sheet1
A1: ACI | B1: APEXFOOT | C1: BXPHARMA | D1: BATBC | E1: Return A | F1: Return B | G1: Return C | H1: Return D | I1: Return A | J1: Return B | K1: Return C | L1: Return D | N1: A | O1: B | P1: C | Q1: D | S1: WA | T1: WB | U1: WC | V1: WD | W1: Total Weight | X1: Real WA | Y1: Real WB | Z1: Real WC | AA1: Real WD | AB1: Effective Weight | AC1: Portfolio Variance | AD1: Portfolio Return | AE1: Sharpe Ratio | AF1: Portfolio Return | AG1: Portfolio Variance | AH1: Real WA | AI1: Real WB | AJ1: Real WC | AK1: Real WD | AM1: MAX SHARPE PORTFOLIO
A2: =aci!H3 -> 200.7 | B2: =apexfoot!H3 -> 214 | C2: =bxpharma!H3 -> 109.2 | D2: =batbc!H3 -> 321.8 | I2: =9.75%/236 -> 0.00041313559 | J2: =9.75%/236 -> 0.00041313559 | K2: =9.75%/236 -> 0.00041313559 | L2: =9.75%/236 -> 0.00041313559 | N2: =_xlfn.VAR.S(I3:I236) -> 0.00073925356 | O2: =_xlfn.COVARIANCE.S(I3:I236,J3:J236) -> 0.00013652219 | P2: =_xlfn.COVARIANCE.S(I3:I236,K3:K236) -> 0.00017929298 | Q2: =_xlfn.COVARIANCE.S(I3:I236,L3:L236) -> 0.00026324614 | S2: 0.08 | T2: 0.01 | U2: 0.74 | V2: 0.05 | W2: =SUM(S2:V2) -> 0.88 | X2: =S2/$W2 -> 0.090909091 | Y2: =T2/$W2 -> 0.011363636 | Z2: =U2/$W2 -> 0.84090909 | AA2: =V2/$W2 -> 0.056818182 | AB2: =SUM(X2:AA2) -> 1 | AC2: {=MMULT(MMULT(X2:AA2,$N$2:$Q$5),TRANSPOSE(X2:AA2))} -> 0.00044327337 | AD2: =SUMPRODUCT(X2:AA2,$E$237:$H$237) -> -0.00030254839 | AE2: =(AD2-$I$2)/SQRT(AC2) -> -0.033992686 | AF2: =AD2 -> -0.00030254839 | AG2: =AC2 -> 0.00044327337 | AH2: =X2 -> 0.090909091 | AI2: =Y2 -> 0.011363636 | AJ2: =Z2 -> 0.84090909 | AK2: =AA2 -> 0.056818182 | AM2: Max Sharpe Ratio | AN2: =MAX(AE2:AE235) -> 0.0076399401
A3: =aci!H4 -> 201.9 | B3: =apexfoot!H4 -> 208.3 | C3: =bxpharma!H4 -> 107.7 | D3: =batbc!H4 -> 320.4 | E3: =LN(A2/A3) -> -0.0059612695 | F3: =LN(B2/B3) -> 0.026996667 | G3: =LN(C2/C3) -> 0.013831479 | H3: =LN(D2/D3) -> 0.0043600194 | I3: =E3-$I$2 -> -0.0063744051 | J3: =F3-$J$2 -> 0.026583531 | K3: =G3-$K$2 -> 0.013418344 | L3: =H3-$L$2 -> 0.0039468838 | N3: =_xlfn.COVARIANCE.S(J3:J236,I3:I236) -> 0.00013652219 | O3: =_xlfn.VAR.S(J3:J236) -> 0.00031653594 | P3: =_xlfn.COVARIANCE.S(J3:J236,K3:K236) -> 7.5283455e-05 | Q3: =_xlfn.COVARIANCE.S(J3:J236,L3:L236) -> 0.00014265668 | S3: 0.74 | T3: 0.64 | U3: 0.67 | V3: 0.56 | W3: =SUM(S3:V3) -> 2.61 | X3: =S3/$W3 -> 0.2835249 | Y3: =T3/$W3 -> 0.24521073 | Z3: =U3/$W3 -> 0.25670498 | AA3: =V3/$W3 -> 0.21455939 | AB3: =SUM(X3:AA3) -> 1 | AC3: {=MMULT(MMULT(X3:AA3,$N$2:$Q$5),TRANSPOSE(X3:AA3))} -> 0.00024025763 | AD3: =SUMPRODUCT(X3:AA3,$E$237:$H$237) -> -0.00016205328 | AE3: =(AD3-$I$2)/SQRT(AC3) -> -0.03710837 | AF3: =AD3 -> -0.00016205328 | AG3: =AC3 -> 0.00024025763 | AH3: =X3 -> 0.2835249 | AI3: =Y3 -> 0.24521073 | AJ3: =Z3 -> 0.25670498 | AK3: =AA3 -> 0.21455939 | AM3: Max Portfolio Return | AN3: =VLOOKUP(AN2,AE2:AF235,2,FALSE()) -> 0.00057818349
A4: =aci!H5 -> 197.5 | B4: =apexfoot!H5 -> 205.6 | C4: =bxpharma!H5 -> 108.8 | D4: =batbc!H5 -> 320.7 | E4: =LN(A3/A4) -> 0.022033941 | F4: =LN(B3/B4) -> 0.013046815 | G4: =LN(C3/C4) -> -0.01016175 | H4: =LN(D3/D4) -> -0.0009358915 | I4: =E4-$I$2 -> 0.021620805 | J4: =F4-$J$2 -> 0.012633679 | K4: =G4-$K$2 -> -0.010574886 | L4: =H4-$L$2 -> -0.0013490271 | N4: =_xlfn.COVARIANCE.S(K3:K236,I3:I236) -> 0.00017929298 | O4: =_xlfn.COVARIANCE.S(K3:K236,J3:J236) -> 7.5283455e-05 | P4: =_xlfn.VAR.S(K3:K236) -> 0.00056180224 | Q4: =_xlfn.COVARIANCE.S(K3:K236,L3:L236) -> 7.0522696e-05 | S4: 0.83 | T4: 0.89 | U4: 0.05 | V4: 0.1 | W4: =SUM(S4:V4) -> 1.87 | X4: =S4/$W4 -> 0.44385027 | Y4: =T4/$W4 -> 0.47593583 | Z4: =U4/$W4 -> 0.026737968 | AA4: =V4/$W4 -> 0.053475936 | AB4: =SUM(X4:AA4) -> 1 | AC4: {=MMULT(MMULT(X4:AA4,$N$2:$Q$5),TRANSPOSE(X4:AA4))} -> 0.0003025046 | AD4: =SUMPRODUCT(X4:AA4,$E$237:$H$237) -> 0.00011753664 | AE4: =(AD4-$I$2)/SQRT(AC4) -> -0.016995615 | AF4: =AD4 -> 0.00011753664 | AG4: =AC4 -> 0.0003025046 | AH4: =X4 -> 0.44385027 | AI4: =Y4 -> 0.47593583 | AJ4: =Z4 -> 0.026737968 | AK4: =AA4 -> 0.053475936 | AM4: Max Portfolio Variance | AN4: =VLOOKUP(AN2,AE2:AG235,3,FALSE()) -> 0.00046670243
A5: =aci!H6 -> 183.9 | B5: =apexfoot!H6 -> 206.9 | C5: =bxpharma!H6 -> 99.1 | D5: =batbc!H6 -> 323.4 | E5: =LN(A4/A5) -> 0.071346453 | F5: =LN(B4/B5) -> -0.0063030512 | G5: =LN(C4/C5) -> 0.093381893 | H5: =LN(D4/D5) -> -0.0083838404 | I5: =E5-$I$2 -> 0.070933317 | J5: =F5-$J$2 -> -0.0067161868 | K5: =G5-$K$2 -> 0.092968757 | L5: =H5-$L$2 -> -0.008796976 | N5: =_xlfn.COVARIANCE.S(L3:L236,I3:I236) -> 0.00026324614 | O5: =_xlfn.COVARIANCE.S(L3:L236,J3:J236) -> 0.00014265668 | P5: =_xlfn.COVARIANCE.S(L3:L236,K3:K236) -> 7.0522696e-05 | Q5: =_xlfn.VAR.S(L3:L236) -> 0.00033475407 | S5: 0.14 | T5: 0.06 | U5: 0.43 | V5: 0.71 | W5: =SUM(S5:V5) -> 1.34 | X5: =S5/$W5 -> 0.10447761 | Y5: =T5/$W5 -> 0.044776119 | Z5: =U5/$W5 -> 0.32089552 | AA5: =V5/$W5 -> 0.52985075 | AB5: =SUM(X5:AA5) -> 1 | AC5: {=MMULT(MMULT(X5:AA5,$N$2:$Q$5),TRANSPOSE(X5:AA5))} -> 0.00023589306 | AD5: =SUMPRODUCT(X5:AA5,$E$237:$H$237) -> -0.00056742214 | AE5: =(AD5-$I$2)/SQRT(AC5) -> -0.063843339 | AF5: =AD5 -> -0.00056742214 | AG5: =AC5 -> 0.00023589306 | AH5: =X5 -> 0.10447761 | AI5: =Y5 -> 0.044776119 | AJ5: =Z5 -> 0.32089552 | AK5: =AA5 -> 0.52985075 | AM5: Weight A | AN5: =VLOOKUP(AN2,AE2:AH235,4,FALSE()) -> 0.70491803
A6: =aci!H7 -> 181.2 | B6: =apexfoot!H7 -> 206 | C6: =bxpharma!H7 -> 101.6 | D6: =batbc!H7 -> 323.9 | E6: =LN(A5/A6) -> 0.014790738 | F6: =LN(B5/B6) -> 0.004359416 | G6: =LN(C5/C6) -> -0.024914094 | H6: =LN(D5/D6) -> -0.001544879 | I6: =E6-$I$2 -> 0.014377602 | J6: =F6-$J$2 -> 0.0039462804 | K6: =G6-$K$2 -> -0.025327229 | L6: =H6-$L$2 -> -0.0019580146 | N6: Risk Free (stray input, see note) | O6: 0.0975 | S6: 0.65 | T6: 0.78 | U6: 0.32 | V6: 0.9 | W6: =SUM(S6:V6) -> 2.65 | X6: =S6/$W6 -> 0.24528302 | Y6: =T6/$W6 -> 0.29433962 | Z6: =U6/$W6 -> 0.12075472 | AA6: =V6/$W6 -> 0.33962264 | AB6: =SUM(X6:AA6) -> 1 | AC6: {=MMULT(MMULT(X6:AA6,$N$2:$Q$5),TRANSPOSE(X6:AA6))} -> 0.00023255313 | AD6: =SUMPRODUCT(X6:AA6,$E$237:$H$237) -> -0.00030460458 | AE6: =(AD6-$I$2)/SQRT(AC6) -> -0.047065878 | AF6: =AD6 -> -0.00030460458 | AG6: =AC6 -> 0.00023255313 | AH6: =X6 -> 0.24528302 | AI6: =Y6 -> 0.29433962 | AJ6: =Z6 -> 0.12075472 | AK6: =AA6 -> 0.33962264 | AM6: Weight B | AN6: =VLOOKUP(AN2,AE2:AI235,5,FALSE()) -> 0.081967213
A7: =aci!H8 -> 179.9 | B7: =apexfoot!H8 -> 203.5 | C7: =bxpharma!H8 -> 101.9 | D7: =batbc!H8 -> 324 | E7: =LN(A6/A7) -> 0.0072002527 | F7: =LN(B6/B7) -> 0.012210164 | G7: =LN(C6/C7) -> -0.0029484051 | H7: =LN(D6/D7) -> -0.00030868962 | I7: =E7-$I$2 -> 0.0067871171 | J7: =F7-$J$2 -> 0.011797028 | K7: =G7-$K$2 -> -0.0033615407 | L7: =H7-$L$2 -> -0.00072182521 | S7: 0.54 | T7: 0.13 | U7: 0.91 | V7: 0.38 | W7: =SUM(S7:V7) -> 1.96 | X7: =S7/$W7 -> 0.2755102 | Y7: =T7/$W7 -> 0.066326531 | Z7: =U7/$W7 -> 0.46428571 | AA7: =V7/$W7 -> 0.19387755 | AB7: =SUM(X7:AA7) -> 1 | AC7: {=MMULT(MMULT(X7:AA7,$N$2:$Q$5),TRANSPOSE(X7:AA7))} -> 0.00029117447 | AD7: =SUMPRODUCT(X7:AA7,$E$237:$H$237) -> -0.00011888236 | AE7: =(AD7-$I$2)/SQRT(AC7) -> -0.0311781 | AF7: =AD7 -> -0.00011888236 | AG7: =AC7 -> 0.00029117447 | AH7: =X7 -> 0.2755102 | AI7: =Y7 -> 0.066326531 | AJ7: =Z7 -> 0.46428571 | AK7: =AA7 -> 0.19387755 | AM7: Weight C | AN7: =VLOOKUP(AN2,AE2:AJ235,6,FALSE()) -> 0.1147541
A8: =aci!H9 -> 178.3 | B8: =apexfoot!H9 -> 204.4 | C8: =bxpharma!H9 -> 94.9 | D8: =batbc!H9 -> 324.2 | E8: =LN(A7/A8) -> 0.0089336161 | F8: =LN(B7/B8) -> -0.0044128534 | G8: =LN(C7/C8) -> 0.071168235 | H8: =LN(D7/D8) -> -0.00061709351 | I8: =E8-$I$2 -> 0.0085204805 | J8: =F8-$J$2 -> -0.004825989 | K8: =G8-$K$2 -> 0.070755099 | L8: =H8-$L$2 -> -0.0010302291 | S8: 0.67 | T8: 0.3 | U8: 0.14 | V8: 0.3 | W8: =SUM(S8:V8) -> 1.41 | X8: =S8/$W8 -> 0.4751773 | Y8: =T8/$W8 -> 0.21276596 | Z8: =U8/$W8 -> 0.09929078 | AA8: =V8/$W8 -> 0.21276596 | AB8: =SUM(X8:AA8) -> 1 | AC8: {=MMULT(MMULT(X8:AA8,$N$2:$Q$5),TRANSPOSE(X8:AA8))} -> 0.00031876993 | AD8: =SUMPRODUCT(X8:AA8,$E$237:$H$237) -> 0.00013462475 | AE8: =(AD8-$I$2)/SQRT(AC8) -> -0.01559924 | AF8: =AD8 -> 0.00013462475 | AG8: =AC8 -> 0.00031876993 | AH8: =X8 -> 0.4751773 | AI8: =Y8 -> 0.21276596 | AJ8: =Z8 -> 0.09929078 | AK8: =AA8 -> 0.21276596 | AM8: Weight D | AN8: =VLOOKUP(AN2,AE2:AK235,7,FALSE()) -> 0.098360656
A9: =aci!H10 -> 173.8 | B9: =apexfoot!H10 -> 204.4 | C9: =bxpharma!H10 -> 87.2 | D9: =batbc!H10 -> 324.2 | E9: =LN(A8/A9) -> 0.025562312 | F9: =LN(B8/B9) -> 0 | G9: =LN(C8/C9) -> 0.084619375 | H9: =LN(D8/D9) -> 0 | I9: =E9-$I$2 -> 0.025149176 | J9: =F9-$J$2 -> -0.00041313559 | K9: =G9-$K$2 -> 0.084206239 | L9: =H9-$L$2 -> -0.00041313559 | S9: 0.24 | T9: 0.11 | U9: 0.29 | V9: 0.37 | W9: =SUM(S9:V9) -> 1.01 | X9: =S9/$W9 -> 0.23762376 | Y9: =T9/$W9 -> 0.10891089 | Z9: =U9/$W9 -> 0.28712871 | AA9: =V9/$W9 -> 0.36633663 | AB9: =SUM(X9:AA9) -> 1 | AC9: {=MMULT(MMULT(X9:AA9,$N$2:$Q$5),TRANSPOSE(X9:AA9))} -> 0.00024502938 | AD9: =SUMPRODUCT(X9:AA9,$E$237:$H$237) -> -0.00028709799 | AE9: =(AD9-$I$2)/SQRT(AC9) -> -0.044733601 | AF9: =AD9 -> -0.00028709799 | AG9: =AC9 -> 0.00024502938 | AH9: =X9 -> 0.23762376 | AI9: =Y9 -> 0.10891089 | AJ9: =Z9 -> 0.28712871 | AK9: =AA9 -> 0.36633663 | AM9: Risk Free Rate | AN9: =O6/235 -> 0.00041489362
A10: =aci!H11 -> 170.7 | B10: =apexfoot!H11 -> 204.8 | C10: =bxpharma!H11 -> 83 | D10: =batbc!H11 -> 324.7 | E10: =LN(A9/A10) -> 0.017997583 | F10: =LN(B9/B10) -> -0.0019550348 | G10: =LN(C9/C10) -> 0.049363723 | H10: =LN(D9/D10) -> -0.0015410698 | I10: =E10-$I$2 -> 0.017584447 | J10: =F10-$J$2 -> -0.0023681704 | K10: =G10-$K$2 -> 0.048950588 | L10: =H10-$L$2 -> -0.0019542054 | S10: 0.12 | T10: 0.7 | U10: 0.9 | V10: 0.23 | W10: =SUM(S10:V10) -> 1.95 | X10: =S10/$W10 -> 0.061538462 | Y10: =T10/$W10 -> 0.35897436 | Z10: =U10/$W10 -> 0.46153846 | AA10: =V10/$W10 -> 0.11794872 | AB10: =SUM(X10:AA10) -> 1 | AC10: {=MMULT(MMULT(X10:AA10,$N$2:$Q$5),TRANSPOSE(X10:AA10))} -> 0.00023266256 | AD10: =SUMPRODUCT(X10:AA10,$E$237:$H$237) -> -0.00046620626 | AE10: =(AD10-$I$2)/SQRT(AC10) -> -0.057649361 | AF10: =AD10 -> -0.00046620626 | AG10: =AC10 -> 0.00023266256 | AH10: =X10 -> 0.061538462 | AI10: =Y10 -> 0.35897436 | AJ10: =Z10 -> 0.46153846 | AK10: =AA10 -> 0.11794872
A11: =aci!H12 -> 168.3 | B11: =apexfoot!H12 -> 204.6 | C11: =bxpharma!H12 -> 80.9 | D11: =batbc!H12 -> 324 | E11: =LN(A10/A11) -> 0.014159529 | F11: =LN(B10/B11) -> 0.00097703965 | G11: =LN(C10/C11) -> 0.025626784 | H11: =LN(D10/D11) -> 0.0021581633 | I11: =E11-$I$2 -> 0.013746393 | J11: =F11-$J$2 -> 0.00056390405 | K11: =G11-$K$2 -> 0.025213648 | L11: =H11-$L$2 -> 0.0017450277 | S11: 0.44 | T11: 0.78 | U11: 0.05 | V11: 0.7 | W11: =SUM(S11:V11) -> 1.97 | X11: =S11/$W11 -> 0.22335025 | Y11: =T11/$W11 -> 0.39593909 | Z11: =U11/$W11 -> 0.025380711 | AA11: =V11/$W11 -> 0.35532995 | AB11: =SUM(X11:AA11) -> 1 | AC11: {=MMULT(MMULT(X11:AA11,$N$2:$Q$5),TRANSPOSE(X11:AA11))} -> 0.00024001677 | AD11: =SUMPRODUCT(X11:AA11,$E$237:$H$237) -> -0.00037121843 | AE11: =(AD11-$I$2)/SQRT(AC11) -> -0.050628066 | AF11: =AD11 -> -0.00037121843 | AG11: =AC11 -> 0.00024001677 | AH11: =X11 -> 0.22335025 | AI11: =Y11 -> 0.39593909 | AJ11: =Z11 -> 0.025380711 | AK11: =AA11 -> 0.35532995 | AM11: Covariance Matrix
A12: =aci!H13 -> 166.7 | B12: =apexfoot!H13 -> 205 | C12: =bxpharma!H13 -> 82.4 | D12: =batbc!H13 -> 324 | E12: =LN(A11/A12) -> 0.0095523114 | F12: =LN(B11/B12) -> -0.0019531256 | G12: =LN(C11/C12) -> -0.018371613 | H12: =LN(D11/D12) -> 0 | I12: =E12-$I$2 -> 0.0091391758 | J12: =F12-$J$2 -> -0.0023662612 | K12: =G12-$K$2 -> -0.018784748 | L12: =H12-$L$2 -> -0.00041313559 | S12: 0.26 | T12: 0.73 | U12: 0.08 | V12: 0.38 | W12: =SUM(S12:V12) -> 1.45 | X12: =S12/$W12 -> 0.17931034 | Y12: =T12/$W12 -> 0.50344828 | Z12: =U12/$W12 -> 0.055172414 | AA12: =V12/$W12 -> 0.26206897 | AB12: =SUM(X12:AA12) -> 1 | AC12: {=MMULT(MMULT(X12:AA12,$N$2:$Q$5),TRANSPOSE(X12:AA12))} -> 0.00022550118 | AD12: =SUMPRODUCT(X12:AA12,$E$237:$H$237) -> -0.00040859832 | AE12: =(AD12-$I$2)/SQRT(AC12) -> -0.05472135 | AF12: =AD12 -> -0.00040859832 | AG12: =AC12 -> 0.00022550118 | AH12: =X12 -> 0.17931034 | AI12: =Y12 -> 0.50344828 | AJ12: =Z12 -> 0.055172414 | AK12: =AA12 -> 0.26206897 | AN12: ACI | AO12: APEXFOOT | AP12: BXPHARMA | AQ12: BATBC
A13: =aci!H14 -> 168.2 | B13: =apexfoot!H14 -> 205 | C13: =bxpharma!H14 -> 81.2 | D13: =batbc!H14 -> 326 | E13: =LN(A12/A13) -> -0.0089579578 | F13: =LN(B12/B13) -> 0 | G13: =LN(C12/C13) -> 0.01467019 | H13: =LN(D12/D13) -> -0.0061538656 | I13: =E13-$I$2 -> -0.0093710934 | J13: =F13-$J$2 -> -0.00041313559 | K13: =G13-$K$2 -> 0.014257054 | L13: =H13-$L$2 -> -0.0065670012 | S13: 0.08 | T13: 0.93 | U13: 0.59 | V13: 0.73 | W13: =SUM(S13:V13) -> 2.33 | X13: =S13/$W13 -> 0.034334764 | Y13: =T13/$W13 -> 0.39914163 | Z13: =U13/$W13 -> 0.25321888 | AA13: =V13/$W13 -> 0.31330472 | AB13: =SUM(X13:AA13) -> 1 | AC13: {=MMULT(MMULT(X13:AA13,$N$2:$Q$5),TRANSPOSE(X13:AA13))} -> 0.00019479221 | AD13: =SUMPRODUCT(X13:AA13,$E$237:$H$237) -> -0.00063121483 | AE13: =(AD13-$I$2)/SQRT(AC13) -> -0.074827366 | AF13: =AD13 -> -0.00063121483 | AG13: =AC13 -> 0.00019479221 | AH13: =X13 -> 0.034334764 | AI13: =Y13 -> 0.39914163 | AJ13: =Z13 -> 0.25321888 | AK13: =AA13 -> 0.31330472 | AM13: ACI | AN13: =N2 -> 0.00073925356 | AO13: =O2 -> 0.00013652219 | AP13: =P2 -> 0.00017929298 | AQ13: =Q2 -> 0.00026324614
A14: =aci!H15 -> 167 | B14: =apexfoot!H15 -> 206.6 | C14: =bxpharma!H15 -> 81.1 | D14: =batbc!H15 -> 328.2 | E14: =LN(A13/A14) -> 0.0071599351 | F14: =LN(B13/B14) -> -0.0077745775 | G14: =LN(C13/C14) -> 0.001232286 | H14: =LN(D13/D14) -> -0.0067257973 | I14: =E14-$I$2 -> 0.0067467995 | J14: =F14-$J$2 -> -0.0081877131 | K14: =G14-$K$2 -> 0.00081915045 | L14: =H14-$L$2 -> -0.0071389329 | S14: 0.06 | T14: 0.09 | U14: 0.69 | V14: 0.96 | W14: =SUM(S14:V14) -> 1.8 | X14: =S14/$W14 -> 0.033333333 | Y14: =T14/$W14 -> 0.05 | Z14: =U14/$W14 -> 0.38333333 | AA14: =V14/$W14 -> 0.53333333 | AB14: =SUM(X14:AA14) -> 1 | AC14: {=MMULT(MMULT(X14:AA14,$N$2:$Q$5),TRANSPOSE(X14:AA14))} -> 0.00023311242 | AD14: =SUMPRODUCT(X14:AA14,$E$237:$H$237) -> -0.00067756149 | AE14: =(AD14-$I$2)/SQRT(AC14) -> -0.07143671 | AF14: =AD14 -> -0.00067756149 | AG14: =AC14 -> 0.00023311242 | AH14: =X14 -> 0.033333333 | AI14: =Y14 -> 0.05 | AJ14: =Z14 -> 0.38333333 | AK14: =AA14 -> 0.53333333 | AM14: APEXFOOT | AN14: =N3 -> 0.00013652219 | AO14: =O3 -> 0.00031653594 | AP14: =P3 -> 7.5283455e-05 | AQ14: =Q3 -> 0.00014265668
A15: =aci!H16 -> 167.3 | B15: =apexfoot!H16 -> 207.5 | C15: =bxpharma!H16 -> 81.3 | D15: =batbc!H16 -> 328.1 | E15: =LN(A14/A15) -> -0.0017947956 | F15: =LN(B14/B15) -> -0.004346783 | G15: =LN(C14/C15) -> -0.0024630554 | H15: =LN(D14/D15) -> 0.00030473869 | I15: =E15-$I$2 -> -0.0022079312 | J15: =F15-$J$2 -> -0.0047599186 | K15: =G15-$K$2 -> -0.002876191 | L15: =H15-$L$2 -> -0.0001083969 | S15: 0.34 | T15: 0.88 | U15: 0.57 | V15: 0.1 | W15: =SUM(S15:V15) -> 1.89 | X15: =S15/$W15 -> 0.17989418 | Y15: =T15/$W15 -> 0.46560847 | Z15: =U15/$W15 -> 0.3015873 | AA15: =V15/$W15 -> 0.052910053 | AB15: =SUM(X15:AA15) -> 1 | AC15: {=MMULT(MMULT(X15:AA15,$N$2:$Q$5),TRANSPOSE(X15:AA15))} -> 0.00022234017 | AD15: =SUMPRODUCT(X15:AA15,$E$237:$H$237) -> -0.00027603784 | AE15: =(AD15-$I$2)/SQRT(AC15) -> -0.046218895 | AF15: =AD15 -> -0.00027603784 | AG15: =AC15 -> 0.00022234017 | AH15: =X15 -> 0.17989418 | AI15: =Y15 -> 0.46560847 | AJ15: =Z15 -> 0.3015873 | AK15: =AA15 -> 0.052910053 | AM15: BXPHARMA | AN15: =N4 -> 0.00017929298 | AO15: =O4 -> 7.5283455e-05 | AP15: =P4 -> 0.00056180224 | AQ15: =Q4 -> 7.0522696e-05
A16: =aci!H17 -> 163.2 | B16: =apexfoot!H17 -> 205.2 | C16: =bxpharma!H17 -> 81 | D16: =batbc!H17 -> 324.9 | E16: =LN(A15/A16) -> 0.024812165 | F16: =LN(B15/B16) -> 0.011146226 | G16: =LN(C15/C16) -> 0.0036968619 | H16: =LN(D15/D16) -> 0.0098009973 | I16: =E16-$I$2 -> 0.02439903 | J16: =F16-$J$2 -> 0.010733091 | K16: =G16-$K$2 -> 0.0032837263 | L16: =H16-$L$2 -> 0.0093878617 | S16: 0.75 | T16: 0.07 | U16: 0.15 | V16: 0.62 | W16: =SUM(S16:V16) -> 1.59 | X16: =S16/$W16 -> 0.47169811 | Y16: =T16/$W16 -> 0.044025157 | Z16: =U16/$W16 -> 0.094339623 | AA16: =V16/$W16 -> 0.38993711 | AB16: =SUM(X16:AA16) -> 1 | AC16: {=MMULT(MMULT(X16:AA16,$N$2:$Q$5),TRANSPOSE(X16:AA16))} -> 0.00035017468 | AD16: =SUMPRODUCT(X16:AA16,$E$237:$H$237) -> 6.6219628e-05 | AE16: =(AD16-$I$2)/SQRT(AC16) -> -0.018538813 | AF16: =AD16 -> 6.6219628e-05 | AG16: =AC16 -> 0.00035017468 | AH16: =X16 -> 0.47169811 | AI16: =Y16 -> 0.044025157 | AJ16: =Z16 -> 0.094339623 | AK16: =AA16 -> 0.38993711 | AM16: BATBC | AN16: =N5 -> 0.00026324614 | AO16: =O5 -> 0.00014265668 | AP16: =P5 -> 7.0522696e-05 | AQ16: =Q5 -> 0.00033475407
A17: =aci!H18 -> 167.9 | B17: =apexfoot!H18 -> 205.9 | C17: =bxpharma!H18 -> 81 | D17: =batbc!H18 -> 324.6 | E17: =LN(A16/A17) -> -0.028392122 | F17: =LN(B16/B17) -> -0.0034055007 | G17: =LN(C16/C17) -> 0 | H17: =LN(D16/D17) -> 0.00092378759 | I17: =E17-$I$2 -> -0.028805257 | J17: =F17-$J$2 -> -0.0038186363 | K17: =G17-$K$2 -> -0.00041313559 | L17: =H17-$L$2 -> 0.000510652 | S17: 0.82 | T17: 0.65 | U17: 0.63 | V17: 0.95 | W17: =SUM(S17:V17) -> 3.05 | X17: =S17/$W17 -> 0.26885246 | Y17: =T17/$W17 -> 0.21311475 | Z17: =U17/$W17 -> 0.20655738 | AA17: =V17/$W17 -> 0.31147541 | AB17: =SUM(X17:AA17) -> 1 | AC17: {=MMULT(MMULT(X17:AA17,$N$2:$Q$5),TRANSPOSE(X17:AA17))} -> 0.00023854607 | AD17: =SUMPRODUCT(X17:AA17,$E$237:$H$237) -> -0.0002331505 | AE17: =(AD17-$I$2)/SQRT(AC17) -> -0.041844528 | AF17: =AD17 -> -0.0002331505 | AG17: =AC17 -> 0.00023854607 | AH17: =X17 -> 0.26885246 | AI17: =Y17 -> 0.21311475 | AJ17: =Z17 -> 0.20655738 | AK17: =AA17 -> 0.31147541 | AM17: Model Notes
A18: =aci!H19 -> 164.1 | B18: =apexfoot!H19 -> 204.9 | C18: =bxpharma!H19 -> 78.5 | D18: =batbc!H19 -> 324.3 | E18: =LN(A17/A18) -> 0.022892566 | F18: =LN(B17/B18) -> 0.0048685588 | G18: =LN(C17/C18) -> 0.03135053 | H18: =LN(D17/D18) -> 0.00092464177 | I18: =E18-$I$2 -> 0.02247943 | J18: =F18-$J$2 -> 0.0044554232 | K18: =G18-$K$2 -> 0.030937394 | L18: =H18-$L$2 -> 0.00051150617 | S18: 0.44 | T18: 0.73 | U18: 0.71 | V18: 0.7 | W18: =SUM(S18:V18) -> 2.58 | X18: =S18/$W18 -> 0.17054264 | Y18: =T18/$W18 -> 0.28294574 | Z18: =U18/$W18 -> 0.2751938 | AA18: =V18/$W18 -> 0.27131783 | AB18: =SUM(X18:AA18) -> 1 | AC18: {=MMULT(MMULT(X18:AA18,$N$2:$Q$5),TRANSPOSE(X18:AA18))} -> 0.00021255525 | AD18: =SUMPRODUCT(X18:AA18,$E$237:$H$237) -> -0.0003740735 | AE18: =(AD18-$I$2)/SQRT(AC18) -> -0.05399508 | AF18: =AD18 -> -0.0003740735 | AG18: =AC18 -> 0.00021255525 | AH18: =X18 -> 0.17054264 | AI18: =Y18 -> 0.28294574 | AJ18: =Z18 -> 0.2751938 | AK18: =AA18 -> 0.27131783 | AM18: Assets: A=ACI, B=APEXFOOT, C=BXPHARMA, D=BATBC.
A19: =aci!H20 -> 165.5 | B19: =apexfoot!H20 -> 206.9 | C19: =bxpharma!H20 -> 78.3 | D19: =batbc!H20 -> 326.6 | E19: =LN(A18/A19) -> -0.0084951967 | F19: =LN(B18/B19) -> -0.0097135295 | G19: =LN(C18/C19) -> 0.0025510218 | H19: =LN(D18/D19) -> -0.0070671672 | I19: =E19-$I$2 -> -0.0089083323 | J19: =F19-$J$2 -> -0.010126665 | K19: =G19-$K$2 -> 0.0021378862 | L19: =H19-$L$2 -> -0.0074803028 | S19: 0.66 | T19: 0.03 | U19: 0.65 | V19: 0.7 | W19: =SUM(S19:V19) -> 2.04 | X19: =S19/$W19 -> 0.32352941 | Y19: =T19/$W19 -> 0.014705882 | Z19: =U19/$W19 -> 0.31862745 | AA19: =V19/$W19 -> 0.34313725 | AB19: =SUM(X19:AA19) -> 1 | AC19: {=MMULT(MMULT(X19:AA19,$N$2:$Q$5),TRANSPOSE(X19:AA19))} -> 0.00028817691 | AD19: =SUMPRODUCT(X19:AA19,$E$237:$H$237) -> -0.0001218041 | AE19: =(AD19-$I$2)/SQRT(AC19) -> -0.031511947 | AF19: =AD19 -> -0.0001218041 | AG19: =AC19 -> 0.00028817691 | AH19: =X19 -> 0.32352941 | AI19: =Y19 -> 0.014705882 | AJ19: =Z19 -> 0.31862745 | AK19: =AA19 -> 0.34313725 | AM19: Price data (aci/apexfoot/bxpharma/batbc tabs) is REAL historical DSE data,
A20: =aci!H21 -> 167.6 | B20: =apexfoot!H21 -> 206.9 | C20: =bxpharma!H21 -> 79.5 | D20: =batbc!H21 -> 327.6 | E20: =LN(A19/A20) -> -0.012608993 | F20: =LN(B19/B20) -> 0 | G20: =LN(C19/C20) -> -0.015209419 | H20: =LN(D19/D20) -> -0.0030571714 | I20: =E20-$I$2 -> -0.013022129 | J20: =F20-$J$2 -> -0.00041313559 | K20: =G20-$K$2 -> -0.015622554 | L20: =H20-$L$2 -> -0.003470307 | S20: 0.82 | T20: 0.53 | U20: 0.57 | V20: 0.71 | W20: =SUM(S20:V20) -> 2.63 | X20: =S20/$W20 -> 0.31178707 | Y20: =T20/$W20 -> 0.20152091 | Z20: =U20/$W20 -> 0.21673004 | AA20: =V20/$W20 -> 0.26996198 | AB20: =SUM(X20:AA20) -> 1 | AC20: {=MMULT(MMULT(X20:AA20,$N$2:$Q$5),TRANSPOSE(X20:AA20))} -> 0.00025155645 | AD20: =SUMPRODUCT(X20:AA20,$E$237:$H$237) -> -0.00014155395 | AE20: =(AD20-$I$2)/SQRT(AC20) -> -0.034972949 | AF20: =AD20 -> -0.00014155395 | AG20: =AC20 -> 0.00025155645 | AH20: =X20 -> 0.31178707 | AI20: =Y20 -> 0.20152091 | AJ20: =Z20 -> 0.21673004 | AK20: =AA20 -> 0.26996198 | AM20: sourced from the Kaggle dataset 'Dhaka Stock Exchange Historical Data
A21: =aci!H22 -> 166.4 | B21: =apexfoot!H22 -> 207.3 | C21: =bxpharma!H22 -> 78.3 | D21: =batbc!H22 -> 327 | E21: =LN(A20/A21) -> 0.0071856597 | F21: =LN(B20/B21) -> -0.0019314347 | G21: =LN(C20/C21) -> 0.015209419 | H21: =LN(D20/D21) -> 0.0018331811 | I21: =E21-$I$2 -> 0.0067725241 | J21: =F21-$J$2 -> -0.0023445703 | K21: =G21-$K$2 -> 0.014796283 | L21: =H21-$L$2 -> 0.0014200455 | S21: 0.78 | T21: 0.59 | U21: 0.61 | V21: 0.9 | W21: =SUM(S21:V21) -> 2.88 | X21: =S21/$W21 -> 0.27083333 | Y21: =T21/$W21 -> 0.20486111 | Z21: =U21/$W21 -> 0.21180556 | AA21: =V21/$W21 -> 0.3125 | AB21: =SUM(X21:AA21) -> 1 | AC21: {=MMULT(MMULT(X21:AA21,$N$2:$Q$5),TRANSPOSE(X21:AA21))} -> 0.00023981693 | AD21: =SUMPRODUCT(X21:AA21,$E$237:$H$237) -> -0.00022878813 | AE21: =(AD21-$I$2)/SQRT(AC21) -> -0.041451811 | AF21: =AD21 -> -0.00022878813 | AG21: =AC21 -> 0.00023981693 | AH21: =X21 -> 0.27083333 | AI21: =Y21 -> 0.20486111 | AJ21: =Z21 -> 0.21180556 | AK21: =AA21 -> 0.3125 | AM21: (1999-2025)' by shazidulislam (also mirrored on Mendeley Data / Harvard
A22: =aci!H23 -> 168.6 | B22: =apexfoot!H23 -> 208.2 | C22: =bxpharma!H23 -> 79 | D22: =batbc!H23 -> 330.7 | E22: =LN(A21/A22) -> -0.013134517 | F22: =LN(B21/B22) -> -0.0043321367 | G22: =LN(C21/C22) -> -0.0089002495 | H22: =LN(D21/D22) -> -0.011251449 | I22: =E22-$I$2 -> -0.013547653 | J22: =F22-$J$2 -> -0.0047452723 | K22: =G22-$K$2 -> -0.0093133851 | L22: =H22-$L$2 -> -0.011664585 | S22: 0.73 | T22: 0.07 | U22: 0.85 | V22: 0.69 | W22: =SUM(S22:V22) -> 2.34 | X22: =S22/$W22 -> 0.31196581 | Y22: =T22/$W22 -> 0.02991453 | Z22: =U22/$W22 -> 0.36324786 | AA22: =V22/$W22 -> 0.29487179 | AB22: =SUM(X22:AA22) -> 1 | AC22: {=MMULT(MMULT(X22:AA22,$N$2:$Q$5),TRANSPOSE(X22:AA22))} -> 0.00028634115 | AD22: =SUMPRODUCT(X22:AA22,$E$237:$H$237) -> -0.0001145488 | AE22: =(AD22-$I$2)/SQRT(AC22) -> -0.031184039 | AF22: =AD22 -> -0.0001145488 | AG22: =AC22 -> 0.00028634115 | AH22: =X22 -> 0.31196581 | AI22: =Y22 -> 0.02991453 | AJ22: =Z22 -> 0.36324786 | AK22: =AA22 -> 0.29487179 | AM22: Dataverse). Filtered to these 4 tickers, common window 2024-04-08 to
A23: =aci!H24 -> 169.6 | B23: =apexfoot!H24 -> 206.9 | C23: =bxpharma!H24 -> 79.2 | D23: =batbc!H24 -> 333.9 | E23: =LN(A22/A23) -> -0.0059136778 | F23: =LN(B22/B23) -> 0.0062635714 | G23: =LN(C22/C23) -> -0.0025284464 | H23: =LN(D22/D23) -> -0.009629927 | I23: =E23-$I$2 -> -0.0063268134 | J23: =F23-$J$2 -> 0.0058504358 | K23: =G23-$K$2 -> -0.0029415819 | L23: =H23-$L$2 -> -0.010043063 | S23: 0.66 | T23: 0.99 | U23: 0.29 | V23: 0.38 | W23: =SUM(S23:V23) -> 2.32 | X23: =S23/$W23 -> 0.28448276 | Y23: =T23/$W23 -> 0.42672414 | Z23: =U23/$W23 -> 0.125 | AA23: =V23/$W23 -> 0.1637931 | AB23: =SUM(X23:AA23) -> 1 | AC23: {=MMULT(MMULT(X23:AA23,$N$2:$Q$5),TRANSPOSE(X23:AA23))} -> 0.00023651762 | AD23: =SUMPRODUCT(X23:AA23,$E$237:$H$237) -> -0.00017458566 | AE23: =(AD23-$I$2)/SQRT(AC23) -> -0.038215509 | AF23: =AD23 -> -0.00017458566 | AG23: =AC23 -> 0.00023651762 | AH23: =X23 -> 0.28448276 | AI23: =Y23 -> 0.42672414 | AJ23: =Z23 -> 0.125 | AK23: =AA23 -> 0.1637931 | AM23: 2025-04-08 (235 real trading days, identical calendar across all 4 stocks).
A24: =aci!H25 -> 159.2 | B24: =apexfoot!H25 -> 203.2 | C24: =bxpharma!H25 -> 78.6 | D24: =batbc!H25 -> 334 | E24: =LN(A23/A24) -> 0.06328145 | F24: =LN(B23/B24) -> 0.018044869 | G24: =LN(C23/C24) -> 0.0076045994 | H24: =LN(D23/D24) -> -0.00029944603 | I24: =E24-$I$2 -> 0.062868314 | J24: =F24-$J$2 -> 0.017631733 | K24: =G24-$K$2 -> 0.0071914638 | L24: =H24-$L$2 -> -0.00071258162 | S24: 0.67 | T24: 0.15 | U24: 0.1 | V24: 0.23 | W24: =SUM(S24:V24) -> 1.15 | X24: =S24/$W24 -> 0.5826087 | Y24: =T24/$W24 -> 0.13043478 | Z24: =U24/$W24 -> 0.086956522 | AA24: =V24/$W24 -> 0.2 | AB24: =SUM(X24:AA24) -> 1 | AC24: {=MMULT(MMULT(X24:AA24,$N$2:$Q$5),TRANSPOSE(X24:AA24))} -> 0.00038581779 | AD24: =SUMPRODUCT(X24:AA24,$E$237:$H$237) -> 0.00032327062 | AE24: =(AD24-$I$2)/SQRT(AC24) -> -0.0045750866 | AF24: =AD24 -> 0.00032327062 | AG24: =AC24 -> 0.00038581779 | AH24: =X24 -> 0.5826087 | AI24: =Y24 -> 0.13043478 | AJ24: =Z24 -> 0.086956522 | AK24: =AA24 -> 0.2 | AM24: TRADE (number of trades) is not present in the source dataset (left blank).
A25: =aci!H26 -> 156.2 | B25: =apexfoot!H26 -> 202.1 | C25: =bxpharma!H26 -> 80.3 | D25: =batbc!H26 -> 346.7 | E25: =LN(A24/A25) -> 0.019024036 | F25: =LN(B24/B25) -> 0.0054280913 | G25: =LN(C24/C25) -> -0.021397922 | H25: =LN(D24/D25) -> -0.03731886 | I25: =E25-$I$2 -> 0.0186109 | J25: =F25-$J$2 -> 0.0050149557 | K25: =G25-$K$2 -> -0.021811057 | L25: =H25-$L$2 -> -0.037731995 | S25: 0.59 | T25: 0.33 | U25: 0.78 | V25: 0.84 | W25: =SUM(S25:V25) -> 2.54 | X25: =S25/$W25 -> 0.23228346 | Y25: =T25/$W25 -> 0.12992126 | Z25: =U25/$W25 -> 0.30708661 | AA25: =V25/$W25 -> 0.33070866 | AB25: =SUM(X25:AA25) -> 1 | AC25: {=MMULT(MMULT(X25:AA25,$N$2:$Q$5),TRANSPOSE(X25:AA25))} -> 0.0002416731 | AD25: =SUMPRODUCT(X25:AA25,$E$237:$H$237) -> -0.00027930004 | AE25: =(AD25-$I$2)/SQRT(AC25) -> -0.044541543 | AF25: =AD25 -> -0.00027930004 | AG25: =AC25 -> 0.0002416731 | AH25: =X25 -> 0.23228346 | AI25: =Y25 -> 0.12992126 | AJ25: =Z25 -> 0.30708661 | AK25: =AA25 -> 0.33070866 | AM25: A handful of halted-trading days (0 Open/High/Low/Volume in source) were
A26: =aci!H27 -> 155.4 | B26: =apexfoot!H27 -> 203 | C26: =bxpharma!H27 -> 79.9 | D26: =batbc!H27 -> 346.7 | E26: =LN(A25/A26) -> 0.0051347995 | F26: =LN(B25/B26) -> -0.0044433546 | G26: =LN(C25/C26) -> 0.0049937682 | H26: =LN(D25/D26) -> 0 | I26: =E26-$I$2 -> 0.0047216639 | J26: =F26-$J$2 -> -0.0048564902 | K26: =G26-$K$2 -> 0.0045806326 | L26: =H26-$L$2 -> -0.00041313559 | S26: 0.59 | T26: 0.21 | U26: 0.94 | V26: 0.16 | W26: =SUM(S26:V26) -> 1.9 | X26: =S26/$W26 -> 0.31052632 | Y26: =T26/$W26 -> 0.11052632 | Z26: =U26/$W26 -> 0.49473684 | AA26: =V26/$W26 -> 0.084210526 | AB26: =SUM(X26:AA26) -> 1 | AC26: {=MMULT(MMULT(X26:AA26,$N$2:$Q$5),TRANSPOSE(X26:AA26))} -> 0.00031002661 | AD26: =SUMPRODUCT(X26:AA26,$E$237:$H$237) -> -1.2677404e-05 | AE26: =(AD26-$I$2)/SQRT(AC26) -> -0.024183515 | AF26: =AD26 -> -1.2677404e-05 | AG26: =AC26 -> 0.00031002661 | AH26: =X26 -> 0.31052632 | AI26: =Y26 -> 0.11052632 | AJ26: =Z26 -> 0.49473684 | AK26: =AA26 -> 0.084210526 | AM26: patched by carrying that day's Close into Open/High/Low; Volume stayed 0.
A27: =aci!H28 -> 155.2 | B27: =apexfoot!H28 -> 201.1 | C27: =bxpharma!H28 -> 78.5 | D27: =batbc!H28 -> 345.6 | E27: =LN(A26/A27) -> 0.0012878302 | F27: =LN(B26/B27) -> 0.0094036823 | G27: =LN(C26/C27) -> 0.017677228 | H27: =LN(D26/D27) -> 0.0031778158 | I27: =E27-$I$2 -> 0.00087469459 | J27: =F27-$J$2 -> 0.0089905467 | K27: =G27-$K$2 -> 0.017264092 | L27: =H27-$L$2 -> 0.0027646802 | S27: 0.73 | T27: 0.91 | U27: 0.41 | V27: 0.28 | W27: =SUM(S27:V27) -> 2.33 | X27: =S27/$W27 -> 0.31330472 | Y27: =T27/$W27 -> 0.39055794 | Z27: =U27/$W27 -> 0.17596567 | AA27: =V27/$W27 -> 0.12017167 | AB27: =SUM(X27:AA27) -> 1 | AC27: {=MMULT(MMULT(X27:AA27,$N$2:$Q$5),TRANSPOSE(X27:AA27))} -> 0.00024280146 | AD27: =SUMPRODUCT(X27:AA27,$E$237:$H$237) -> -9.7028706e-05 | AE27: =(AD27-$I$2)/SQRT(AC27) -> -0.032740433 | AF27: =AD27 -> -9.7028706e-05 | AG27: =AC27 -> 0.00024280146 | AH27: =X27 -> 0.31330472 | AI27: =Y27 -> 0.39055794 | AJ27: =Z27 -> 0.17596567 | AK27: =AA27 -> 0.12017167
A28: =aci!H29 -> 153.1 | B28: =apexfoot!H29 -> 201.2 | C28: =bxpharma!H29 -> 77.8 | D28: =batbc!H29 -> 345.8 | E28: =LN(A27/A28) -> 0.013623305 | F28: =LN(B27/B28) -> -0.00049714145 | G28: =LN(C27/C28) -> 0.0089571936 | H28: =LN(D27/D28) -> -0.00057853632 | I28: =E28-$I$2 -> 0.013210169 | J28: =F28-$J$2 -> -0.00091027704 | K28: =G28-$K$2 -> 0.008544058 | L28: =H28-$L$2 -> -0.00099167191 | S28: 0.25 | T28: 0.71 | U28: 0.63 | V28: 0.23 | W28: =SUM(S28:V28) -> 1.82 | X28: =S28/$W28 -> 0.13736264 | Y28: =T28/$W28 -> 0.39010989 | Z28: =U28/$W28 -> 0.34615385 | AA28: =V28/$W28 -> 0.12637363 | AB28: =SUM(X28:AA28) -> 1 | AC28: {=MMULT(MMULT(X28:AA28,$N$2:$Q$5),TRANSPOSE(X28:AA28))} -> 0.00021617275 | AD28: =SUMPRODUCT(X28:AA28,$E$237:$H$237) -> -0.00036477459 | AE28: =(AD28-$I$2)/SQRT(AC28) -> -0.052908931 | AF28: =AD28 -> -0.00036477459 | AG28: =AC28 -> 0.00021617275 | AH28: =X28 -> 0.13736264 | AI28: =Y28 -> 0.39010989 | AJ28: =Z28 -> 0.34615385 | AK28: =AA28 -> 0.12637363 | AM28: NOTE: the 234 simulated portfolio weights (columns S:V) have been
A29: =aci!H30 -> 151.9 | B29: =apexfoot!H30 -> 202.3 | C29: =bxpharma!H30 -> 76.7 | D29: =batbc!H30 -> 339 | E29: =LN(A28/A29) -> 0.0078688931 | F29: =LN(B28/B29) -> -0.0054523059 | G29: =LN(C28/C29) -> 0.014239723 | H29: =LN(D28/D29) -> 0.019860466 | I29: =E29-$I$2 -> 0.0074557575 | J29: =F29-$J$2 -> -0.0058654415 | K29: =G29-$K$2 -> 0.013826587 | L29: =H29-$L$2 -> 0.01944733 | S29: 0.15 | T29: 0.29 | U29: 0.68 | V29: 0.94 | W29: =SUM(S29:V29) -> 2.06 | X29: =S29/$W29 -> 0.072815534 | Y29: =T29/$W29 -> 0.1407767 | Z29: =U29/$W29 -> 0.33009709 | AA29: =V29/$W29 -> 0.45631068 | AB29: =SUM(X29:AA29) -> 1 | AC29: {=MMULT(MMULT(X29:AA29,$N$2:$Q$5),TRANSPOSE(X29:AA29))} -> 0.00021659274 | AD29: =SUMPRODUCT(X29:AA29,$E$237:$H$237) -> -0.00059499838 | AE29: =(AD29-$I$2)/SQRT(AC29) -> -0.068500903 | AF29: =AD29 -> -0.00059499838 | AG29: =AC29 -> 0.00021659274 | AH29: =X29 -> 0.072815534 | AI29: =Y29 -> 0.1407767 | AJ29: =Z29 -> 0.33009709 | AK29: =AA29 -> 0.45631068 | AM29: FROZEN to fixed values (no longer live RANDBETWEEN formulas), so the
A30: =aci!H31 -> 152.8 | B30: =apexfoot!H31 -> 201.2 | C30: =bxpharma!H31 -> 76.6 | D30: =batbc!H31 -> 341.3 | E30: =LN(A29/A30) -> -0.0059074671 | F30: =LN(B29/B30) -> 0.0054523059 | G30: =LN(C29/C30) -> 0.0013046316 | H30: =LN(D29/D30) -> -0.0067617485 | I30: =E30-$I$2 -> -0.0063206027 | J30: =F30-$J$2 -> 0.0050391704 | K30: =G30-$K$2 -> 0.00089149603 | L30: =H30-$L$2 -> -0.0071748841 | S30: 0.55 | T30: 0.57 | U30: 0.85 | V30: 0.01 | W30: =SUM(S30:V30) -> 1.98 | X30: =S30/$W30 -> 0.27777778 | Y30: =T30/$W30 -> 0.28787879 | Z30: =U30/$W30 -> 0.42929293 | AA30: =V30/$W30 -> 0.0050505051 | AB30: =SUM(X30:AA30) -> 1 | AC30: {=MMULT(MMULT(X30:AA30,$N$2:$Q$5),TRANSPOSE(X30:AA30))} -> 0.00027148026 | AD30: =SUMPRODUCT(X30:AA30,$E$237:$H$237) -> -5.8186783e-05 | AE30: =(AD30-$I$2)/SQRT(AC30) -> -0.02860546 | AF30: =AD30 -> -5.8186783e-05 | AG30: =AC30 -> 0.00027148026 | AH30: =X30 -> 0.27777778 | AI30: =Y30 -> 0.28787879 | AJ30: =Z30 -> 0.42929293 | AK30: =AA30 -> 0.0050505051 | AM30: results reported here match this file exactly, every time it is opened.
A31: =aci!H32 -> 152.9 | B31: =apexfoot!H32 -> 202.3 | C31: =bxpharma!H32 -> 78 | D31: =batbc!H32 -> 344.7 | E31: =LN(A30/A31) -> -0.0006542362 | F31: =LN(B30/B31) -> -0.0054523059 | G31: =LN(C30/C31) -> -0.01811175 | H31: =LN(D30/D31) -> -0.0099126176 | I31: =E31-$I$2 -> -0.0010673718 | J31: =F31-$J$2 -> -0.0058654415 | K31: =G31-$K$2 -> -0.018524886 | L31: =H31-$L$2 -> -0.010325753 | S31: 0.26 | T31: 0.74 | U31: 0.59 | V31: 0.72 | W31: =SUM(S31:V31) -> 2.31 | X31: =S31/$W31 -> 0.11255411 | Y31: =T31/$W31 -> 0.32034632 | Z31: =U31/$W31 -> 0.25541126 | AA31: =V31/$W31 -> 0.31168831 | AB31: =SUM(X31:AA31) -> 1 | AC31: {=MMULT(MMULT(X31:AA31,$N$2:$Q$5),TRANSPOSE(X31:AA31))} -> 0.00020167861 | AD31: =SUMPRODUCT(X31:AA31,$E$237:$H$237) -> -0.0004938233 | AE31: =(AD31-$I$2)/SQRT(AC31) -> -0.063864231 | AF31: =AD31 -> -0.0004938233 | AG31: =AC31 -> 0.00020167861 | AH31: =X31 -> 0.11255411 | AI31: =Y31 -> 0.32034632 | AJ31: =Z31 -> 0.25541126 | AK31: =AA31 -> 0.31168831 | AM31: NEWER one -- an exact sign inversion of every return (confirmed: it
A32: =aci!H33 -> 153 | B32: =apexfoot!H33 -> 200.9 | C32: =bxpharma!H33 -> 77.8 | D32: =batbc!H33 -> 346.7 | E32: =LN(A31/A32) -> -0.00065380846 | F32: =LN(B31/B32) -> 0.0069444724 | G32: =LN(C31/C32) -> 0.0025673955 | H32: =LN(D31/D32) -> -0.0057853792 | I32: =E32-$I$2 -> -0.0010669441 | J32: =F32-$J$2 -> 0.0065313368 | K32: =G32-$K$2 -> 0.0021542599 | L32: =H32-$L$2 -> -0.0061985148 | S32: 0.03 | T32: 0.03 | U32: 0.95 | V32: 0.89 | W32: =SUM(S32:V32) -> 1.9 | X32: =S32/$W32 -> 0.015789474 | Y32: =T32/$W32 -> 0.015789474 | Z32: =U32/$W32 -> 0.5 | AA32: =V32/$W32 -> 0.46842105 | AB32: =SUM(X32:AA32) -> 1 | AC32: {=MMULT(MMULT(X32:AA32,$N$2:$Q$5),TRANSPOSE(X32:AA32))} -> 0.00025729117 | AD32: =SUMPRODUCT(X32:AA32,$E$237:$H$237) -> -0.00065762836 | AE32: =(AD32-$I$2)/SQRT(AC32) -> -0.066754616 | AF32: =AD32 -> -0.00065762836 | AG32: =AC32 -> 0.00025729117 | AH32: =X32 -> 0.015789474 | AI32: =Y32 -> 0.015789474 | AJ32: =Z32 -> 0.5 | AK32: =AA32 -> 0.46842105 | AM32: reported -25.7% for a stock that actually gained +29.3%). Covariance/
A33: =aci!H34 -> 152.6 | B33: =apexfoot!H34 -> 201.9 | C33: =bxpharma!H34 -> 76.5 | D33: =batbc!H34 -> 346.7 | E33: =LN(A32/A33) -> 0.0026178025 | F33: =LN(B32/B33) -> -0.0049652535 | G33: =LN(C32/C33) -> 0.01685069 | H33: =LN(D32/D33) -> 0 | I33: =E33-$I$2 -> 0.0022046669 | J33: =F33-$J$2 -> -0.0053783891 | K33: =G33-$K$2 -> 0.016437555 | L33: =H33-$L$2 -> -0.00041313559 | S33: 0.09 | T33: 0.29 | U33: 0.49 | V33: 0.09 | W33: =SUM(S33:V33) -> 0.96 | X33: =S33/$W33 -> 0.09375 | Y33: =T33/$W33 -> 0.30208333 | Z33: =U33/$W33 -> 0.51041667 | AA33: =V33/$W33 -> 0.09375 | AB33: =SUM(X33:AA33) -> 1 | AC33: {=MMULT(MMULT(X33:AA33,$N$2:$Q$5),TRANSPOSE(X33:AA33))} -> 0.00025225247 | AD33: =SUMPRODUCT(X33:AA33,$E$237:$H$237) -> -0.00038994905 | AE33: =(AD33-$I$2)/SQRT(AC33) -> -0.050564254 | AF33: =AD33 -> -0.00038994905 | AG33: =AC33 -> 0.00025225247 | AH33: =X33 -> 0.09375 | AI33: =Y33 -> 0.30208333 | AJ33: =Z33 -> 0.51041667 | AK33: =AA33 -> 0.09375 | AM33: variance are unaffected by a uniform sign flip, but Average Return,
A34: =aci!H35 -> 153.3 | B34: =apexfoot!H35 -> 200.7 | C34: =bxpharma!H35 -> 76.4 | D34: =batbc!H35 -> 348.7 | E34: =LN(A33/A34) -> -0.004576667 | F34: =LN(B33/B34) -> 0.0059612695 | G34: =LN(C33/C34) -> 0.0013080447 | H34: =LN(D33/D34) -> -0.005752101 | I34: =E34-$I$2 -> -0.0049898026 | J34: =F34-$J$2 -> 0.0055481339 | K34: =G34-$K$2 -> 0.00089490907 | L34: =H34-$L$2 -> -0.0061652366 | S34: 0.36 | T34: 0.15 | U34: 0.48 | V34: 0.47 | W34: =SUM(S34:V34) -> 1.46 | X34: =S34/$W34 -> 0.24657534 | Y34: =T34/$W34 -> 0.10273973 | Z34: =U34/$W34 -> 0.32876712 | AA34: =V34/$W34 -> 0.32191781 | AB34: =SUM(X34:AA34) -> 1 | AC34: {=MMULT(MMULT(X34:AA34,$N$2:$Q$5),TRANSPOSE(X34:AA34))} -> 0.00025092959 | AD34: =SUMPRODUCT(X34:AA34,$E$237:$H$237) -> -0.0002461387 | AE34: =(AD34-$I$2)/SQRT(AC34) -> -0.041618862 | AF34: =AD34 -> -0.0002461387 | AG34: =AC34 -> 0.00025092959 | AH34: =X34 -> 0.24657534 | AI34: =Y34 -> 0.10273973 | AJ34: =Z34 -> 0.32876712 | AK34: =AA34 -> 0.32191781 | AM34: Portfolio Return and the Sharpe ratio numerator were all backwards.
A35: =aci!H36 -> 153.9 | B35: =apexfoot!H36 -> 201.6 | C35: =bxpharma!H36 -> 76.6 | D35: =batbc!H36 -> 346.8 | E35: =LN(A34/A35) -> -0.003906255 | F35: =LN(B34/B35) -> -0.0044742804 | G35: =LN(C34/C35) -> -0.0026143806 | H35: =LN(D34/D35) -> 0.0054637088 | I35: =E35-$I$2 -> -0.0043193906 | J35: =F35-$J$2 -> -0.004887416 | K35: =G35-$K$2 -> -0.0030275162 | L35: =H35-$L$2 -> 0.0050505732 | S35: 0.34 | T35: 0.02 | U35: 0.85 | V35: 0.39 | W35: =SUM(S35:V35) -> 1.6 | X35: =S35/$W35 -> 0.2125 | Y35: =T35/$W35 -> 0.0125 | Z35: =U35/$W35 -> 0.53125 | AA35: =V35/$W35 -> 0.24375 | AB35: =SUM(X35:AA35) -> 1 | AC35: {=MMULT(MMULT(X35:AA35,$N$2:$Q$5),TRANSPOSE(X35:AA35))} -> 0.00030048636 | AD35: =SUMPRODUCT(X35:AA35,$E$237:$H$237) -> -0.00022976816 | AE35: =(AD35-$I$2)/SQRT(AC35) -> -0.037088014 | AF35: =AD35 -> -0.00022976816 | AG35: =AC35 -> 0.00030048636 | AH35: =X35 -> 0.2125 | AI35: =Y35 -> 0.0125 | AJ35: =Z35 -> 0.53125 | AK35: =AA35 -> 0.24375 | AM35: Fixed to LN(row-1/row), the correct forward-in-time direction.
A36: =aci!H37 -> 153.4 | B36: =apexfoot!H37 -> 203.2 | C36: =bxpharma!H37 -> 76.6 | D36: =batbc!H37 -> 346.9 | E36: =LN(A35/A36) -> 0.0032541519 | F36: =LN(B35/B36) -> -0.0079051795 | G36: =LN(C35/C36) -> 0 | H36: =LN(D35/D36) -> -0.00028830907 | I36: =E36-$I$2 -> 0.0028410163 | J36: =F36-$J$2 -> -0.0083183151 | K36: =G36-$K$2 -> -0.00041313559 | L36: =H36-$L$2 -> -0.00070144466 | S36: 0.07 | T36: 0.67 | U36: 0.88 | V36: 0.87 | W36: =SUM(S36:V36) -> 2.49 | X36: =S36/$W36 -> 0.02811245 | Y36: =T36/$W36 -> 0.26907631 | Z36: =U36/$W36 -> 0.35341365 | AA36: =V36/$W36 -> 0.34939759 | AB36: =SUM(X36:AA36) -> 1 | AC36: {=MMULT(MMULT(X36:AA36,$N$2:$Q$5),TRANSPOSE(X36:AA36))} -> 0.00020389609 | AD36: =SUMPRODUCT(X36:AA36,$E$237:$H$237) -> -0.00063038162 | AE36: =(AD36-$I$2)/SQRT(AC36) -> -0.073079433 | AF36: =AD36 -> -0.00063038162 | AG36: =AC36 -> 0.00020389609 | AH36: =X36 -> 0.02811245 | AI36: =Y36 -> 0.26907631 | AJ36: =Z36 -> 0.35341365 | AK36: =AA36 -> 0.34939759 | AM36: 2) Portfolio Return formula: the original referenced a single day's
A37: =aci!H38 -> 151.6 | B37: =apexfoot!H38 -> 200.6 | C37: =bxpharma!H38 -> 76.2 | D37: =batbc!H38 -> 349.3 | E37: =LN(A36/A37) -> 0.011803416 | F37: =LN(B36/B37) -> 0.01287784 | G37: =LN(C36/C37) -> 0.0052356141 | H37: =LN(D36/D37) -> -0.0068945978 | I37: =E37-$I$2 -> 0.01139028 | J37: =F37-$J$2 -> 0.012464705 | K37: =G37-$K$2 -> 0.0048224785 | L37: =H37-$L$2 -> -0.0073077334 | S37: 0.52 | T37: 0.91 | U37: 0.88 | V37: 0.48 | W37: =SUM(S37:V37) -> 2.79 | X37: =S37/$W37 -> 0.18637993 | Y37: =T37/$W37 -> 0.32616487 | Z37: =U37/$W37 -> 0.31541219 | AA37: =V37/$W37 -> 0.17204301 | AB37: =SUM(X37:AA37) -> 1 | AC37: {=MMULT(MMULT(X37:AA37,$N$2:$Q$5),TRANSPOSE(X37:AA37))} -> 0.00021886756 | AD37: =SUMPRODUCT(X37:AA37,$E$237:$H$237) -> -0.0003025239 | AE37: =(AD37-$I$2)/SQRT(AC37) -> -0.048374416 | AF37: =AD37 -> -0.0003025239 | AG37: =AC37 -> 0.00021886756 | AH37: =X37 -> 0.18637993 | AI37: =Y37 -> 0.32616487 | AJ37: =Z37 -> 0.31541219 | AK37: =AA37 -> 0.17204301 | AM37: return instead of the AVERAGE(row3:235) row it had already built but
A38: =aci!H39 -> 149.7 | B38: =apexfoot!H39 -> 199.2 | C38: =bxpharma!H39 -> 77.2 | D38: =batbc!H39 -> 350.9 | E38: =LN(A37/A38) -> 0.012612182 | F38: =LN(B37/B38) -> 0.0070035304 | G38: =LN(C37/C38) -> -0.013037994 | H38: =LN(D37/D38) -> -0.0045701308 | I38: =E38-$I$2 -> 0.012199046 | J38: =F38-$J$2 -> 0.0065903948 | K38: =G38-$K$2 -> -0.01345113 | L38: =H38-$L$2 -> -0.0049832664 | S38: 0.53 | T38: 0.54 | U38: 0.08 | V38: 0.67 | W38: =SUM(S38:V38) -> 1.82 | X38: =S38/$W38 -> 0.29120879 | Y38: =T38/$W38 -> 0.2967033 | Z38: =U38/$W38 -> 0.043956044 | AA38: =V38/$W38 -> 0.36813187 | AB38: =SUM(X38:AA38) -> 1 | AC38: {=MMULT(MMULT(X38:AA38,$N$2:$Q$5),TRANSPOSE(X38:AA38))} -> 0.00025704096 | AD38: =SUMPRODUCT(X38:AA38,$E$237:$H$237) -> -0.00025291203 | AE38: =(AD38-$I$2)/SQRT(AC38) -> -0.041543598 | AF38: =AD38 -> -0.00025291203 | AG38: =AC38 -> 0.00025704096 | AH38: =X38 -> 0.29120879 | AI38: =Y38 -> 0.2967033 | AJ38: =Z38 -> 0.043956044 | AK38: =AA38 -> 0.36813187 | AM38: never wired in (an off-by-one reference bug). Fixed to use a genuine
A39: =aci!H40 -> 147.7 | B39: =apexfoot!H40 -> 199.6 | C39: =bxpharma!H40 -> 77.1 | D39: =batbc!H40 -> 350.1 | E39: =LN(A38/A39) -> 0.013450102 | F39: =LN(B38/B39) -> -0.0020060187 | G39: =LN(C38/C39) -> 0.0012961765 | H39: =LN(D38/D39) -> 0.0022824546 | I39: =E39-$I$2 -> 0.013036966 | J39: =F39-$J$2 -> -0.0024191543 | K39: =G39-$K$2 -> 0.00088304087 | L39: =H39-$L$2 -> 0.001869319 | S39: 0.93 | T39: 0.94 | U39: 0.8 | V39: 0.8 | W39: =SUM(S39:V39) -> 3.47 | X39: =S39/$W39 -> 0.26801153 | Y39: =T39/$W39 -> 0.27089337 | Z39: =U39/$W39 -> 0.23054755 | AA39: =V39/$W39 -> 0.23054755 | AB39: =SUM(X39:AA39) -> 1 | AC39: {=MMULT(MMULT(X39:AA39,$N$2:$Q$5),TRANSPOSE(X39:AA39))} -> 0.00023321448 | AD39: =SUMPRODUCT(X39:AA39,$E$237:$H$237) -> -0.00020090566 | AE39: =(AD39-$I$2)/SQRT(AC39) -> -0.040208678 | AF39: =AD39 -> -0.00020090566 | AG39: =AC39 -> 0.00023321448 | AH39: =X39 -> 0.26801153 | AI39: =Y39 -> 0.27089337 | AJ39: =Z39 -> 0.23054755 | AK39: =AA39 -> 0.23054755 | AM39: AVERAGE(row 3:236) per asset (row 237) as the expected-return input.
A40: =aci!H41 -> 147.2 | B40: =apexfoot!H41 -> 200.5 | C40: =bxpharma!H41 -> 78.7 | D40: =batbc!H41 -> 353.3 | E40: =LN(A39/A40) -> 0.0033909832 | F40: =LN(B39/B40) -> -0.0044988829 | G40: =LN(C39/C40) -> -0.020539875 | H40: =LN(D39/D40) -> -0.0090987264 | I40: =E40-$I$2 -> 0.0029778476 | J40: =F40-$J$2 -> -0.0049120185 | K40: =G40-$K$2 -> -0.02095301 | L40: =H40-$L$2 -> -0.009511862 | S40: 0.54 | T40: 0.46 | U40: 0.55 | V40: 0.25 | W40: =SUM(S40:V40) -> 1.8 | X40: =S40/$W40 -> 0.3 | Y40: =T40/$W40 -> 0.25555556 | Z40: =U40/$W40 -> 0.30555556 | AA40: =V40/$W40 -> 0.13888889 | AB40: =SUM(X40:AA40) -> 1 | AC40: {=MMULT(MMULT(X40:AA40,$N$2:$Q$5),TRANSPOSE(X40:AA40))} -> 0.00024972579 | AD40: =SUMPRODUCT(X40:AA40,$E$237:$H$237) -> -9.5459941e-05 | AE40: =(AD40-$I$2)/SQRT(AC40) -> -0.032184061 | AF40: =AD40 -> -9.5459941e-05 | AG40: =AC40 -> 0.00024972579 | AH40: =X40 -> 0.3 | AI40: =Y40 -> 0.25555556 | AJ40: =Z40 -> 0.30555556 | AK40: =AA40 -> 0.13888889
...

Sheet aci
A1: # | B1: DATE | C1: TRADING CODE | D1: LTP* | E1: HIGH | F1: LOW | G1: OPENP* | H1: CLOSEP* | I1: YCP | J1: TRADE | K1: VALUE (mn) | L1: VOLUME | N1: Source
N2: Kaggle: Dhaka Stock Exchange Historical Data (1999-2025), by shazidulislam (also mirrored on Mendeley Data / Harvard Dataverse). Real DSE daily OHLCV, filtered to this ticker, 2024-04-08 to 2025-04-08. TRADE (number of trades) is not present in the source dataset and is left blank.
A3: 1 | B3: 45755 | C3: ACI | D3: 200.7 | E3: 204.9 | F3: 199.1 | G3: 201.8 | H3: 200.7 | I3: 201.9 | K3: 78.805 | L3: 392652
A4: 2 | B4: 45754 | C4: ACI | D4: 201.9 | E4: 207.8 | F4: 198.9 | G4: 199.4 | H4: 201.9 | I4: 197.5 | K4: 144.459 | L4: 715499
A5: 3 | B5: 45753 | C5: ACI | D5: 197.5 | E5: 199 | F5: 180.1 | G5: 180.1 | H5: 197.5 | I5: 183.9 | K5: 51.276 | L5: 259623
A6: 4 | B6: 45743 | C6: ACI | D6: 183.9 | E6: 185 | F6: 179.4 | G6: 181.9 | H6: 183.9 | I6: 181.2 | K6: 29.477 | L6: 160287
A7: 5 | B7: 45741 | C7: ACI | D7: 181.2 | E7: 182.3 | F7: 179 | G7: 180 | H7: 181.2 | I7: 179.9 | K7: 28.197 | L7: 155612
A8: 6 | B8: 45740 | C8: ACI | D8: 179.9 | E8: 182 | F8: 178.1 | G8: 178.3 | H8: 179.9 | I8: 178.3 | K8: 31.893 | L8: 177280
A9: 7 | B9: 45739 | C9: ACI | D9: 178.3 | E9: 179.5 | F9: 173.1 | G9: 173.8 | H9: 178.3 | I9: 173.8 | K9: 30.603 | L9: 171638
A10: 8 | B10: 45736 | C10: ACI | D10: 173.8 | E10: 174.1 | F10: 170.7 | G10: 170.7 | H10: 173.8 | I10: 170.7 | K10: 21.037 | L10: 121041
A11: 9 | B11: 45735 | C11: ACI | D11: 170.7 | E11: 174.9 | F11: 167.7 | G11: 169 | H11: 170.7 | I11: 168.3 | K11: 16.354 | L11: 95807
A12: 10 | B12: 45734 | C12: ACI | D12: 168.3 | E12: 168.9 | F12: 165.3 | G12: 165.3 | H12: 168.3 | I12: 166.7 | K12: 6.129 | L12: 36418
A13: 11 | B13: 45733 | C13: ACI | D13: 166.7 | E13: 168.5 | F13: 165.5 | G13: 165.6 | H13: 166.7 | I13: 168.2 | K13: 5.286 | L13: 31710
A14: 12 | B14: 45732 | C14: ACI | D14: 168.2 | E14: 169 | F14: 165 | G14: 166.8 | H14: 168.2 | I14: 167 | K14: 6.29 | L14: 37393
... A237: 235 | B237: 45390 | C237: ACI | D237: 155.2 | E237: 159 | F237: 153.5 | G237: 159 | H237: 155.2 | I237: 155.2 | K237: 0.715 | L237: 4610

Sheet apexfoot
A1: # | B1: DATE | C1: TRADING CODE | D1: LTP* | E1: HIGH | F1: LOW | G1: OPENP* | H1: CLOSEP* | I1: YCP | J1: TRADE | K1: VALUE (mn) | L1: VOLUME | N1: Source
N2: Kaggle: Dhaka Stock Exchange Historical Data (1999-2025), by shazidulislam (also mirrored on Mendeley Data / Harvard Dataverse). Real DSE daily OHLCV, filtered to this ticker, 2024-04-08 to 2025-04-08. TRADE (number of trades) is not present in the source dataset and is left blank.
A3: 1 | B3: 45755 | C3: APEXFOOT | D3: 214 | E3: 214.5 | F3: 209.7 | G3: 210.2 | H3: 214 | I3: 208.3 | K3: 20.365 | L3: 95162
A4: 2 | B4: 45754 | C4: APEXFOOT | D4: 208.3 | E4: 214.7 | F4: 205.2 | G4: 206.4 | H4: 208.3 | I4: 205.6 | K4: 11.977 | L4: 57497
A5: 3 | B5: 45753 | C5: APEXFOOT | D5: 205.6 | E5: 205.8 | F5: 200.1 | G5: 204 | H5: 205.6 | I5: 206.9 | K5: 1.64 | L5: 7979
A6: 4 | B6: 45743 | C6: APEXFOOT | D6: 206.9 | E6: 208.9 | F6: 205 | G6: 206.7 | H6: 206.9 | I6: 206 | K6: 1.267 | L6: 6124
A7: 5 | B7: 45741 | C7: APEXFOOT | D7: 206 | E7: 207.5 | F7: 204.2 | G7: 207.5 | H7: 206 | I7: 203.5 | K7: 1.035 | L7: 5023
A8: 6 | B8: 45740 | C8: APEXFOOT | D8: 203.5 | E8: 206.8 | F8: 203.1 | G8: 206.8 | H8: 203.5 | I8: 204.4 | K8: 1.255 | L8: 6166
A9: 7 | B9: 45739 | C9: APEXFOOT | D9: 204.4 | E9: 207.5 | F9: 203.8 | G9: 205.1 | H9: 204.4 | I9: 204.4 | K9: 2.178 | L9: 10655
A10: 8 | B10: 45736 | C10: APEXFOOT | D10: 204.4 | E10: 206.7 | F10: 204 | G10: 206.7 | H10: 204.4 | I10: 204.8 | K10: 2.22 | L10: 10863
A11: 9 | B11: 45735 | C11: APEXFOOT | D11: 204.8 | E11: 206.5 | F11: 204.5 | G11: 206.5 | H11: 204.8 | I11: 204.6 | K11: 1.622 | L11: 7918
A12: 10 | B12: 45734 | C12: APEXFOOT | D12: 204.6 | E12: 207 | F12: 203 | G12: 207 | H12: 204.6 | I12: 205 | K12: 3.248 | L12: 15877
A13: 11 | B13: 45733 | C13: APEXFOOT | D13: 205 | E13: 207 | F13: 204.6 | G13: 207 | H13: 205 | I13: 205 | K13: 1.545 | L13: 7539
A14: 12 | B14: 45732 | C14: APEXFOOT | D14: 205 | E14: 207.9 | F14: 203 | G14: 207.9 | H14: 205 | I14: 206.6 | K14: 3.102 | L14: 15130
... A237: 235 | B237: 45390 | C237: APEXFOOT | D237: 248.8 | E237: 249.9 | F237: 245.8 | G237: 247.9 | H237: 248.8 | I237: 248.8 | K237: 0.725 | L237: 2912

Sheet bxpharma
A1: # | B1: DATE | C1: TRADING CODE | D1: LTP* | E1: HIGH | F1: LOW | G1: OPENP* | H1: CLOSEP* | I1: YCP | J1: TRADE | K1: VALUE (mn) | L1: VOLUME | N1: Source
N2: Kaggle: Dhaka Stock Exchange Historical Data (1999-2025), by shazidulislam (also mirrored on Mendeley Data / Harvard Dataverse). Real DSE daily OHLCV, filtered to this ticker, 2024-04-08 to 2025-04-08. TRADE (number of trades) is not present in the source dataset and is left blank.
A3: 1 | B3: 45755 | C3: BXPHARMA | D3: 109.2 | E3: 111.8 | F3: 105.9 | G3: 107.5 | H3: 109.2 | I3: 107.7 | K3: 241.001 | L3: 2206972
A4: 2 | B4: 45754 | C4: BXPHARMA | D4: 107.7 | E4: 113.3 | F4: 106.7 | G4: 110.9 | H4: 107.7 | I4: 108.8 | K4: 263.773 | L4: 2449146
A5: 3 | B5: 45753 | C5: BXPHARMA | D5: 108.8 | E5: 109 | F5: 93.3 | G5: 98 | H5: 108.8 | I5: 99.1 | K5: 325.439 | L5: 2991166
A6: 4 | B6: 45743 | C6: BXPHARMA | D6: 99.1 | E6: 101.9 | F6: 97.9 | G6: 101.4 | H6: 99.1 | I6: 101.6 | K6: 151.396 | L6: 1527708
A7: 5 | B7: 45741 | C7: BXPHARMA | D7: 101.6 | E7: 104.4 | F7: 100.5 | G7: 102 | H7: 101.6 | I7: 101.9 | K7: 192.958 | L7: 1899197
A8: 6 | B8: 45740 | C8: BXPHARMA | D8: 101.9 | E8: 104.3 | F8: 94.9 | G8: 95 | H8: 101.9 | I8: 94.9 | K8: 317.016 | L8: 3111051
A9: 7 | B9: 45739 | C9: BXPHARMA | D9: 94.9 | E9: 95.9 | F9: 87 | G9: 87 | H9: 94.9 | I9: 87.2 | K9: 213.158 | L9: 2246134
A10: 8 | B10: 45736 | C10: BXPHARMA | D10: 87.2 | E10: 88.2 | F10: 83 | G10: 83 | H10: 87.2 | I10: 83 | K10: 128.299 | L10: 1471323
A11: 9 | B11: 45735 | C11: BXPHARMA | D11: 83 | E11: 83.5 | F11: 80.9 | G11: 81.5 | H11: 83 | I11: 80.9 | K11: 53.115 | L11: 639943
A12: 10 | B12: 45734 | C12: BXPHARMA | D12: 80.9 | E12: 81.9 | F12: 80.6 | G12: 81.4 | H12: 80.9 | I12: 82.4 | K12: 11.202 | L12: 138470
A13: 11 | B13: 45733 | C13: BXPHARMA | D13: 82.4 | E13: 82.7 | F13: 80.6 | G13: 81.5 | H13: 82.4 | I13: 81.2 | K13: 56.918 | L13: 690754
A14: 12 | B14: 45732 | C14: BXPHARMA | D14: 81.2 | E14: 82.5 | F14: 80.6 | G14: 81 | H14: 81.2 | I14: 81.1 | K14: 12.67 | L14: 156040
... A237: 235 | B237: 45390 | C237: BXPHARMA | D237: 120 | E237: 120 | F237: 114.2 | G237: 119 | H237: 120 | I237: 120 | K237: 33.653 | L237: 280439

Sheet batbc
A1: # | B1: DATE | C1: TRADING CODE | D1: LTP* | E1: HIGH | F1: LOW | G1: OPENP* | H1: CLOSEP* | I1: YCP | J1: TRADE | K1: VALUE (mn) | L1: VOLUME | N1: Source
N2: Kaggle: Dhaka Stock Exchange Historical Data (1999-2025), by shazidulislam (also mirrored on Mendeley Data / Harvard Dataverse). Real DSE daily OHLCV, filtered to this ticker, 2024-04-08 to 2025-04-08. TRADE (number of trades) is not present in the source dataset and is left blank.
A3: 1 | B3: 45755 | C3: BATBC | D3: 321.8 | E3: 322.8 | F3: 319.7 | G3: 320.4 | H3: 321.8 | I3: 320.4 | K3: 15.674 | L3: 48706
A4: 2 | B4: 45754 | C4: BATBC | D4: 320.4 | E4: 323.9 | F4: 319.7 | G4: 319.7 | H4: 320.4 | I4: 320.7 | K4: 18.163 | L4: 56688
A5: 3 | B5: 45753 | C5: BATBC | D5: 320.7 | E5: 323.5 | F5: 319.5 | G5: 323.5 | H5: 320.7 | I5: 323.4 | K5: 14.808 | L5: 46173
A6: 4 | B6: 45743 | C6: BATBC | D6: 323.4 | E6: 324.6 | F6: 323.1 | G6: 324.6 | H6: 323.4 | I6: 323.9 | K6: 11.113 | L6: 34363
A7: 5 | B7: 45741 | C7: BATBC | D7: 323.9 | E7: 324.9 | F7: 322.6 | G7: 324.9 | H7: 323.9 | I7: 324 | K7: 16.388 | L7: 50595
A8: 6 | B8: 45740 | C8: BATBC | D8: 324 | E8: 324.9 | F8: 323.8 | G8: 324.1 | H8: 324 | I8: 324.2 | K8: 18.339 | L8: 56603
A9: 7 | B9: 45739 | C9: BATBC | D9: 324.2 | E9: 325 | F9: 324 | G9: 325 | H9: 324.2 | I9: 324.2 | K9: 15.717 | L9: 48479
A10: 8 | B10: 45736 | C10: BATBC | D10: 324.2 | E10: 326 | F10: 323.1 | G10: 324.9 | H10: 324.2 | I10: 324.7 | K10: 9.904 | L10: 30548
A11: 9 | B11: 45735 | C11: BATBC | D11: 324.7 | E11: 326.9 | F11: 323 | G11: 326.9 | H11: 324.7 | I11: 324 | K11: 13.878 | L11: 42740
A12: 10 | B12: 45734 | C12: BATBC | D12: 324 | E12: 324.5 | F12: 323.7 | G12: 324.1 | H12: 324 | I12: 324 | K12: 10.742 | L12: 33153
A13: 11 | B13: 45733 | C13: BATBC | D13: 324 | E13: 327.4 | F13: 323.4 | G13: 326 | H13: 324 | I13: 326 | K13: 12.23 | L13: 37748
A14: 12 | B14: 45732 | C14: BATBC | D14: 326 | E14: 329.8 | F14: 325.4 | G14: 328.2 | H14: 326 | I14: 328.2 | K14: 20.127 | L14: 61739
... A237: 235 | B237: 45390 | C237: BATBC | D237: 405.6 | E237: 406.9 | F237: 402.8 | G237: 405 | H237: 405.6 | I237: 405.6 | K237: 27.029 | L237: 66639
